Workbook

Sheet 01_Visao_Geral
A1: ARQUITETURA INICIAL DA PLATAFORMA HUB
A3: Primeiro dimensionamento funcional para, no segundo momento, transformar escopo em custo real de produto, tecnologia, dados e operação.
A5: Código | B5: Frente / módulo | C5: Público | D5: Modelo | E5: Standalone? | F5: O que resolve | G5: Integrações | H5: Leitura | I5: MOD (Tecnica)
A6: CORE | B6: Core / Plataforma | C6: Transversal | D6: Base comum | E6: Sim | F6: Autenticação, perfis, permissões, consentimentos, integrações, notificações, analytics e administração. | G6: Todas as frentes usam o Core. | H6: Obrigatório para qualquer implantação. | I6: MOD-01
A7: ED | B7: Estratégia & Dados | C7: Empresas | D7: Produto independente | E7: Sim | F7: Conecta dados internos de pessoas e negócio para diagnóstico, prioridades, planos de ação e ROI. | G7: Pode receber dados de RH/ERP/BI sem usar candidatos, fornecedores, acadêmico ou eventos. | H7: Pode ser vendido sozinho. | I7: MOD-08
A8: COL | B8: Colaboradores / Meu Time | C8: Empresas | D8: Independente ou conectado a ED | E8: Sim | F8: Desempenho, competências, desenvolvimento, liderança, saúde do time e talentos internos. | G8: Alimenta ED com sinais de pessoas e recebe prioridades/planos. | H8: Pode operar sem marketplace externo. | I8: MOD-02/03
A9: CAN | B9: Candidatos & Carreira | C9: Pessoas + Empresas | D9: Marketplace / jornada | E9: Sim | F9: Perfil, competências, capacitação, oportunidades, candidatura, match e acompanhamento. | G9: Conversa com Acadêmico, Empresas, Eventos e Core. | H9: Vertical de empregabilidade. | I9: MOD-03
A10: FOR | B10: Fornecedores & Negócios | C10: Fornecedores + Compradores | D10: Marketplace B2B | E10: Sim | F10: Maturidade, demandas, desenvolvimento, match, negociação e conversão. | G10: Conversa com Eventos, ED e Core. | H10: Pode operar sozinho para acesso a mercado. | I10: MOD-05
A11: ACA | B11: Acadêmico / Universidades | C11: Alunos + Universidades + Empresas | D11: Educação-mercado | E11: Sim | F11: Projetos, bolsas, pesquisa aplicada, estágio, carreira, formação e conexão com empresas. | G11: Conversa fortemente com Candidatos e Empresas; opcionalmente Eventos. | H11: Pode ser vendido sozinho para universidade. | I11: MOD-06
A12: EVT | B12: Eventos | C12: Organizadores + Público + Empresas | D12: Orquestrador transversal | E12: Parcial | F12: Talentos, fornecedores, pesquisa, patrocínios, acessibilidade, segurança/assédio e ROI. | G12: Consome Candidatos, Fornecedores e Dados; pode ativar Acadêmico. | H12: Pode começar standalone, mas ganha valor com outros módulos. | I12: MOD-07
A13: COM | B13: Comunidades / Eu & Eu / Cultura | C13: Pessoas | D13: Jornada individual | E13: Sim | F13: Perfil, objetivos, plano, preparação, mentoria, cuidado, eventos e conexões. | G13: Pode alimentar Candidatos, Acadêmico e Eventos com consentimento. | H13: Camada B2C; não é pré-requisito B2B. | I13: MOD-07
A14: CUST | B14: Clientes & Receita | C14: Empresas/CS | D14: Independente ou conectado a ED | E14: Sim | F14: Contas, contratos, NPS, churn, receita e margem por cliente. | G14: CRM/ERP; alimenta ED/HUB Impact. | H14: Novo — MOD-04 Tecnica (MVP). | I14: MOD-04
A16: PRINCÍPIO DE ARQUITETURA

Sheet 02_Inventario_Paginas
A1: INVENTÁRIO DE PÁGINAS / TELAS
A5: ID | B5: Código | C5: Frente | D5: Página / tela | E5: Canal | F5: Fase | G5: Complexidade | H5: Compartilhável? | I5: Dependência | J5: Observação | K5: MOD (Tecnica) | L5: Fase Tecnica | M5: Ref Tecnica
A6: 1 | B6: CORE | C6: Core / Plataforma | D6: Login / SSO | E6: Web | F6: MVP | G6: Baixa | H6: Sim | I6: - | J6: Autenticação | K6: MOD-01 | L6: MVP (F0/MVP1) | M6: INT-08/BL-001
A7: 2 | B7: CORE | C7: Core / Plataforma | D7: Cadastro / onboarding | E7: Web/Mobile | F7: MVP | G7: Média | H7: Sim | I7: - | J7: Entrada por tipo | K7: MOD-01 | L7: MVP (F0/MVP1) | M7: BL-001
A8: 3 | B8: CORE | C8: Core / Plataforma | D8: Perfis e organizações | E8: Web | F8: MVP | G8: Média | H8: Sim | I8: - | J8: Entidades | K8: MOD-01 | L8: MVP (F0/MVP1) | M8: BL-001
A9: 4 | B9: CORE | C9: Core / Plataforma | D9: Papéis e permissões | E9: Admin | F9: MVP | G9: Alta | H9: Sim | I9: - | J9: RBAC | K9: MOD-01 | L9: MVP (F0/MVP1) | M9: GOV-03/BL-016
A10: 5 | B10: CORE | C10: Core / Plataforma | D10: Consentimentos / LGPD | E10: Web/Admin | F10: MVP | G10: Alta | H10: Sim | I10: - | J10: Privacidade | K10: MOD-01 | L10: MVP (F0/MVP1) | M10: GOV-01/GOV-04
A11: 6 | B11: CORE | C11: Core / Plataforma | D11: Central de integrações | E11: Admin | F11: MVP | G11: Alta | H11: Sim | I11: - | J11: APIs/RHIS/ERP/CRM/LMS | K11: MOD-01 | L11: MVP (F0/MVP1) | M11: INT-01..06/BL-002..005
A12: 7 | B12: CORE | C12: Core / Plataforma | D12: Notificações | E12: Web/Mobile | F12: MVP | G12: Média | H12: Sim | I12: - | J12: Gatilhos | K12: MOD-01 | L12: MVP (F0/MVP1) | M12: BL-010
A13: 8 | B13: CORE | C13: Core / Plataforma | D13: Mensagens | E13: Web/Mobile | F13: Fase 2 | G13: Alta | H13: Sim | I13: - | J13: Conversas | K13: MOD-01 | L13: Fase 2 | M13: sem ref direta (Fase 2)
A14: 9 | B14: CORE | C14: Core / Plataforma | D14: Busca global | E14: Web | F14: Fase 2 | G14: Média | H14: Sim | I14: - | J14: Busca | K14: MOD-01 | L14: Fase 2 | M14: sem ref direta (Fase 2)
A15: 10 | B15: CORE | C15: Core / Plataforma | D15: Analytics de uso | E15: Admin | F15: MVP | G15: Média | H15: Sim | I15: - | J15: Adoção | K15: MOD-01 | L15: MVP (F0/MVP1) | M15: KPI-HUB-01/BL-014
A16: 11 | B16: CORE | C16: Core / Plataforma | D16: Administração | E16: Admin | F16: MVP | G16: Alta | H16: Sim | I16: - | J16: Configurações | K16: MOD-01 | L16: MVP (F0/MVP1) | M16: BL-001
A17: 12 | B17: CORE | C17: Core / Plataforma | D17: Auditoria e logs | E17: Admin | F17: MVP | G17: Alta | H17: Sim | I17: - | J17: Rastreabilidade | K17: MOD-01 | L17: MVP (F0/MVP1) | M17: GOV-09/SRC-12
... A116: 111 | B116: CUST | C116: Clientes & Receita | D116: Expansão e rentabilidade | E116: Web | F116: MVP | G116: Alta | H116: Não | I116: CORE | J116: Upsell e mix | K116: MOD-04 | L116: MVP (MVP1) | M116: SCR-01

Sheet 03_Resumo_Modulos
A1: RESUMO DE ESCOPO POR MÓDULO
A5: Código | B5: Módulo | C5: Total telas | D5: MVP | E5: Fase 2 | F5: Alta/Muito alta | G5: Standalone? | H5: Leitura | I5: MVP+1
A6: CORE | B6: Core / Plataforma | C6: =COUNTIF('02_Inventario_Paginas'!$B$6:$B$200,A6) | D6: =COUNTIFS('02_Inventario_Paginas'!$B$6:$B$200,A6,'02_Inventario_Paginas'!$F$6:$F$200,"MVP") | E6: =COUNTIFS('02_Inventario_Paginas'!$B$6:$B$200,A6,'02_Inventario_Paginas'!$F$6:$F$200,"Fase 2") | F6: =COUNTIFS('02_Inventario_Paginas'!$B$6:$B$200,A6,'02_Inventario_Paginas'!$G$6:$G$200,"Alta")+COUNTIFS('02_Inventario_Paginas'!$B$6:$B$200,A6,'02_Inventario_Paginas'!$G$6:$G$200,"Muito alta") | G6: Sim | H6: Obrigatório para qualquer implantação. | I6: =COUNTIFS('02_Inventario_Paginas'!$B$6:$B$200,A6,'02_Inventario_Paginas'!$F$6:$F$200,"MVP+1")
A7: ED | B7: Estratégia & Dados | C7: =COUNTIF('02_Inventario_Paginas'!$B$6:$B$200,A7) | D7: =COUNTIFS('02_Inventario_Paginas'!$B$6:$B$200,A7,'02_Inventario_Paginas'!$F$6:$F$200,"MVP") | E7: =COUNTIFS('02_Inventario_Paginas'!$B$6:$B$200,A7,'02_Inventario_Paginas'!$F$6:$F$200,"Fase 2") | F7: =COUNTIFS('02_Inventario_Paginas'!$B$6:$B$200,A7,'02_Inventario_Paginas'!$G$6:$G$200,"Alta")+COUNTIFS('02_Inventario_Paginas'!$B$6:$B$200,A7,'02_Inventario_Paginas'!$G$6:$G$200,"Muito alta") | G7: Sim | H7: Pode ser vendido sozinho. | I7: =COUNTIFS('02_Inventario_Paginas'!$B$6:$B$200,A7,'02_Inventario_Paginas'!$F$6:$F$200,"MVP+1")
A8: COL | B8: Colaboradores / Meu Time | C8: =COUNTIF('02_Inventario_Paginas'!$B$6:$B$200,A8) | D8: =COUNTIFS('02_Inventario_Paginas'!$B$6:$B$200,A8,'02_Inventario_Paginas'!$F$6:$F$200,"MVP") | E8: =COUNTIFS('02_Inventario_Paginas'!$B$6:$B$200,A8,'02_Inventario_Paginas'!$F$6:$F$200,"Fase 2") | F8: =COUNTIFS('02_Inventario_Paginas'!$B$6:$B$200,A8,'02_Inventario_Paginas'!$G$6:$G$200,"Alta")+COUNTIFS('02_Inventario_Paginas'!$B$6:$B$200,A8,'02_Inventario_Paginas'!$G$6:$G$200,"Muito alta") | G8: Sim | H8: Pode operar sem marketplace externo. | I8: =COUNTIFS('02_Inventario_Paginas'!$B$6:$B$200,A8,'02_Inventario_Paginas'!$F$6:$F$200,"MVP+1")
A9: CAN | B9: Candidatos & Carreira | C9: =COUNTIF('02_Inventario_Paginas'!$B$6:$B$200,A9) | D9: =COUNTIFS('02_Inventario_Paginas'!$B$6:$B$200,A9,'02_Inventario_Paginas'!$F$6:$F$200,"MVP") | E9: =COUNTIFS('02_Inventario_Paginas'!$B$6:$B$200,A9,'02_Inventario_Paginas'!$F$6:$F$200,"Fase 2") | F9: =COUNTIFS('02_Inventario_Paginas'!$B$6:$B$200,A9,'02_Inventario_Paginas'!$G$6:$G$200,"Alta")+COUNTIFS('02_Inventario_Paginas'!$B$6:$B$200,A9,'02_Inventario_Paginas'!$G$6:$G$200,"Muito alta") | G9: Sim | H9: Vertical de empregabilidade. | I9: =COUNTIFS('02_Inventario_Paginas'!$B$6:$B$200,A9,'02_Inventario_Paginas'!$F$6:$F$200,"MVP+1")
A10: FOR | B10: Fornecedores & Negócios | C10: =COUNTIF('02_Inventario_Paginas'!$B$6:$B$200,A10) | D10: =COUNTIFS('02_Inventario_Paginas'!$B$6:$B$200,A10,'02_Inventario_Paginas'!$F$6:$F$200,"MVP") | E10: =COUNTIFS('02_Inventario_Paginas'!$B$6:$B$200,A10,'02_Inventario_Paginas'!$F$6:$F$200,"Fase 2") | F10: =COUNTIFS('02_Inventario_Paginas'!$B$6:$B$200,A10,'02_Inventario_Paginas'!$G$6:$G$200,"Alta")+COUNTIFS('02_Inventario_Paginas'!$B$6:$B$200,A10,'02_Inventario_Paginas'!$G$6:$G$200,"Muito alta") | G10: Sim | H10: Pode operar sozinho para acesso a mercado. | I10: =COUNTIFS('02_Inventario_Paginas'!$B$6:$B$200,A10,'02_Inventario_Paginas'!$F$6:$F$200,"MVP+1")
A11: ACA | B11: Acadêmico / Universidades | C11: =COUNTIF('02_Inventario_Paginas'!$B$6:$B$200,A11) | D11: =COUNTIFS('02_Inventario_Paginas'!$B$6:$B$200,A11,'02_Inventario_Paginas'!$F$6:$F$200,"MVP") | E11: =COUNTIFS('02_Inventario_Paginas'!$B$6:$B$200,A11,'02_Inventario_Paginas'!$F$6:$F$200,"Fase 2") | F11: =COUNTIFS('02_Inventario_Paginas'!$B$6:$B$200,A11,'02_Inventario_Paginas'!$G$6:$G$200,"Alta")+COUNTIFS('02_Inventario_Paginas'!$B$6:$B$200,A11,'02_Inventario_Paginas'!$G$6:$G$200,"Muito alta") | G11: Sim | H11: Pode ser vendido sozinho para universidade. | I11: =COUNTIFS('02_Inventario_Paginas'!$B$6:$B$200,A11,'02_Inventario_Paginas'!$F$6:$F$200,"MVP+1")
A12: EVT | B12: Eventos | C12: =COUNTIF('02_Inventario_Paginas'!$B$6:$B$200,A12) | D12: =COUNTIFS('02_Inventario_Paginas'!$B$6:$B$200,A12,'02_Inventario_Paginas'!$F$6:$F$200,"MVP") | E12: =COUNTIFS('02_Inventario_Paginas'!$B$6:$B$200,A12,'02_Inventario_Paginas'!$F$6:$F$200,"Fase 2") | F12: =COUNTIFS('02_Inventario_Paginas'!$B$6:$B$200,A12,'02_Inventario_Paginas'!$G$6:$G$200,"Alta")+COUNTIFS('02_Inventario_Paginas'!$B$6:$B$200,A12,'02_Inventario_Paginas'!$G$6:$G$200,"Muito alta") | G12: Parcial | H12: Pode começar standalone, mas ganha valor com outros módulos. | I12: =COUNTIFS('02_Inventario_Paginas'!$B$6:$B$200,A12,'02_Inventario_Paginas'!$F$6:$F$200,"MVP+1")
A13: COM | B13: Comunidades / Eu & Eu / Cultura | C13: =COUNTIF('02_Inventario_Paginas'!$B$6:$B$200,A13) | D13: =COUNTIFS('02_Inventario_Paginas'!$B$6:$B$200,A13,'02_Inventario_Paginas'!$F$6:$F$200,"MVP") | E13: =COUNTIFS('02_Inventario_Paginas'!$B$6:$B$200,A13,'02_Inventario_Paginas'!$F$6:$F$200,"Fase 2") | F13: =COUNTIFS('02_Inventario_Paginas'!$B$6:$B$200,A13,'02_Inventario_Paginas'!$G$6:$G$200,"Alta")+COUNTIFS('02_Inventario_Paginas'!$B$6:$B$200,A13,'02_Inventario_Paginas'!$G$6:$G$200,"Muito alta") | G13: Sim | H13: Camada B2C; não é pré-requisito B2B. | I13: =COUNTIFS('02_Inventario_Paginas'!$B$6:$B$200,A13,'02_Inventario_Paginas'!$F$6:$F$200,"MVP+1")
A14: CUST | B14: Clientes & Receita | C14: =COUNTIF('02_Inventario_Paginas'!$B$6:$B$200,A14) | D14: =COUNTIFS('02_Inventario_Paginas'!$B$6:$B$200,A14,'02_Inventario_Paginas'!$F$6:$F$200,"MVP") | E14: =COUNTIFS('02_Inventario_Paginas'!$B$6:$B$200,A14,'02_Inventario_Paginas'!$F$6:$F$200,"Fase 2") | F14: =COUNTIFS('02_Inventario_Paginas'!$B$6:$B$200,A14,'02_Inventario_Paginas'!$G$6:$G$200,"Alta")+COUNTIFS('02_Inventario_Paginas'!$B$6:$B$200,A14,'02_Inventario_Paginas'!$G$6:$G$200,"Muito alta") | G14: Sim | H14: Novo — MOD-04 Tecnica (MVP); CRM/NPS/churn. | I14: =COUNTIFS('02_Inventario_Paginas'!$B$6:$B$200,A14,'02_Inventario_Paginas'!$F$6:$F$200,"MVP+1")

Sheet 04_Matriz_Integracoes
A1: MATRIZ DE INTEGRAÇÃO ENTRE FRENTES
A3: 3 = mesmo módulo | 2 = integração direta/forte | 1 = opcional/troca de dados | 0 = não precisa conversar diretamente
A5: Código | B5: Módulo | C5: MOD-01 | D5: MOD-02 | E5: MOD-03 | F5: MOD-04 | G5: MOD-05 | H5: MOD-06 | I5: MOD-07 | J5: MOD-08
A6: MOD-01 | B6: HUB Core | C6: 3 | D6: 2 | E6: 2 | F6: 2 | G6: 2 | H6: 2 | I6: 2 | J6: 2
A7: MOD-02 | B7: Performance | C7: 2 | D7: 3 | E7: 2 | F7: 2 | G7: 0 | H7: 0 | I7: 0 | J7: 2
A8: MOD-03 | B8: Pessoas e Talentos | C8: 2 | D8: 2 | E8: 3 | F8: 1 | G8: 0 | H8: 2 | I8: 1 | J8: 2
A9: MOD-04 | B9: Clientes e Receita | C9: 2 | D9: 2 | E9: 1 | F9: 3 | G9: 1 | H9: 0 | I9: 1 | J9: 2
A10: MOD-05 | B10: Fornecedores e Compras | C10: 2 | D10: 0 | E10: 0 | F10: 1 | G10: 3 | H10: 0 | I10: 2 | J10: 1
A11: MOD-06 | B11: Acadêmico | C11: 2 | D11: 0 | E11: 2 | F11: 0 | G11: 0 | H11: 3 | I11: 2 | J11: 1
A12: MOD-07 | B12: Comunidades e Eventos | C12: 2 | D12: 0 | E12: 1 | F12: 1 | G12: 2 | H12: 2 | I12: 3 | J12: 1
A13: MOD-08 | B13: HUB Impact | C13: 2 | D13: 2 | E13: 2 | F13: 2 | G13: 1 | H13: 1 | I13: 1 | J13: 3

Sheet 05_Fluxos_Diretos
A1: O QUE CONVERSA DIRETAMENTE — E O QUE NÃO PRECISA
A5: Origem | B5: Destino | C5: Tipo | D5: Dado compartilhado | E5: Por que integrar | F5: Obrigatória? | G5: Funciona sem? | H5: Exemplo
A6: MOD-08 HUB Impact | B6: MOD-02 Performance | C6: Direta | D6: KPIs, skills, desempenho, liderança | E6: Enriquece pessoas x negócio | F6: Não | G6: Sim | H6: ED pode usar RHIS/ERP/BI sem COL.
A7: MOD-08 HUB Impact | B7: MOD-07 | C7: Direta | D7: Pesquisa, receita, custos, fornecedores, equipes | E7: Conecta operação ao ROI | F7: Não | G7: Sim | H7: EVT pode enviar dados agregados.
A8: MOD-08 HUB Impact | B8: MOD-05 | C8: Opcional | D8: Spend, conversão, impacto | E8: Analisa cadeia e negócios | F8: Não | G8: Sim | H8: ED não depende do marketplace B2B.
A9: MOD-08 HUB Impact | B9: MOD-03 | C9: Opcional | D9: Funil, contratação, skills | E9: Relaciona atração e performance | F9: Não | G9: Sim | H9: Pode usar ATS existente.
A10: MOD-03 | B10: MOD-06 | C10: Direta | D10: Perfil, skills, formação, projetos, estágio | E10: Formação -> empregabilidade | F10: Não | G10: Sim | H10: ACA pode ter oportunidades próprias.
A11: MOD-03 | B11: MOD-07 | C11: Direta | D11: Talentos temporários e vagas | E11: Contratação para eventos | F11: Não | G11: Sim | H11: EVT pode integrar ATS externo.
A12: MOD-05 | B12: MOD-07 | C12: Direta | D12: Fornecedores, demandas, docs, contratos | E12: Compras do evento | F12: Não | G12: Sim | H12: EVT pode cadastrar base própria.
A13: MOD-06 | B13: Empresas/MOD-03 | C13: Direta | D13: Projetos, bolsas, estágios, pesquisa | E13: Universidade -> mercado | F13: Não | G13: Sim | H13: ACA pode começar isolado.
A14: MOD-07 | B14: MOD-03 | C14: Direta c/ consentimento | D14: Perfil, objetivos, preparação | E14: Evita recadastro | F14: Não | G14: Sim | H14: CAN pode ter onboarding próprio.
A15: MOD-07 | B15: MOD-07 | C15: Direta c/ consentimento | D15: Interesses, presença, pesquisa | E15: Personaliza experiência | F15: Não | G15: Sim | H15: EVT pode operar com base própria.
A16: MOD-03 | B16: MOD-05 | C16: Sem integração direta | D16: - | E16: Marketplaces diferentes | F16: Não | G16: Sim | H16: Cruza apenas em casos via Core/Eventos.
... A18: MOD-02 Performance | B18: MOD-04 Clientes e Receita | C18: Direta | D18: Metas e entrega por conta | E18: Liga esforço a resultado do cliente | F18: Não | G18: Sim | H18: SCR-01

Sheet 06_Cenarios_Implantacao
A1: CENÁRIOS DE IMPLANTAÇÃO MODULAR
A5: Cenário | B5: MOD-01 | C5: MOD-02 | D5: MOD-03 | E5: MOD-04 | F5: MOD-05 | G5: MOD-06 | H5: MOD-07 | I5: MOD-08 | J5: Leitura
A6: Estratégia & Dados standalone | B6: ✓ | C6: — | D6: — | E6: — | F6: — | G6: — | H6: — | I6: ✓ | J6: Dados do cliente via INT-01..06; sem marketplaces.
A7: Gestão de pessoas completa | B7: ✓ | C7: ✓ | D7: Opcional (MVP+1) | E7: — | F7: — | G7: — | H7: — | I7: ✓ | J7: MOD-02 no MVP; MOD-03 em MVP+1.
A8: Empregabilidade | B8: ✓ | C8: — | D8: ✓ | E8: — | F8: — | G8: — | H8: Opcional | I8: — | J8: Formação + matching; MOD-07 apoia preparação.
A9: Fornecedores | B9: ✓ | C9: — | D9: — | E9: — | F9: ✓ | G9: — | H9: Opcional | I9: Opcional | J9: Match B2B; MOD-08 mede impacto.
A10: Universidade | B10: ✓ | C10: — | D10: ✓ | E10: — | F10: — | G10: ✓ | H10: Opcional | I10: Opcional | J10: MOD-06 Fase 2; MOD-03 amplia carreira.
A11: HUB Eventos | B11: ✓ | C11: — | D11: ✓ | E11: — | F11: ✓ | G11: — | H11: ✓ | I11: Opcional | J11: Orquestra talentos, fornecedores e ROI.
A12: Ecossistema completo | B12: ✓ | C12: ✓ | D12: ✓ | E12: ✓ | F12: ✓ | G12: ✓ | H12: ✓ | I12: ✓ | J12: Máxima inteligência de rede, com consentimento e governança.
A13: Piloto Monks (MVP) | B13: ✓ | C13: ✓ | D13: — | E13: ✓ | F13: — | G13: — | H13: — | I13: ✓ | J13: PIL-01..05; SCR-01..07; decisão Tecnica #3.
A14: Motor de dados + Performance (híbrido) | B14: ✓ | C14: ✓ | D14: — | E14: Opcional | F14: — | G14: — | H14: — | I14: ✓ | J14: Decisão Tecnica #3: híbrido.

Sheet 07_Base_Para_Precificacao
A1: BASE PARA A PRÓXIMA ETAPA DE PRECIFICAÇÃO
A3: Sem valores ainda: drivers que serão convertidos em horas, equipe, infraestrutura, licenças e custos recorrentes.
A5: Código | B5: Módulo | C5: Telas | D5: Complexas | E5: Integrações diretas | F5: IA/matching | G5: Dados/BI | H5: Mensageria | I5: Mobile | J5: Compliance | K5: Operação humana | L5: Observação
A6: CORE | B6: Core / Plataforma | C6: =COUNTIF('02_Inventario_Paginas'!$B$6:$B$200,A6) | D6: =COUNTIFS('02_Inventario_Paginas'!$B$6:$B$200,A6,'02_Inventario_Paginas'!$G$6:$G$200,"Alta")+COUNTIFS('02_Inventario_Paginas'!$B$6:$B$200,A6,'02_Inventario_Paginas'!$G$6:$G$200,"Muito alta") | E6: 7 | F6: Não | G6: Média | H6: Alta | I6: Sim | J6: Muito alta | K6: Média | L6: Infraestrutura transversal
A7: ED | B7: Estratégia & Dados | C7: =COUNTIF('02_Inventario_Paginas'!$B$6:$B$200,A7) | D7: =COUNTIFS('02_Inventario_Paginas'!$B$6:$B$200,A7,'02_Inventario_Paginas'!$G$6:$G$200,"Alta")+COUNTIFS('02_Inventario_Paginas'!$B$6:$B$200,A7,'02_Inventario_Paginas'!$G$6:$G$200,"Muito alta") | E7: 3 | F7: Alta | G7: Muito alta | H7: Baixa | I7: Não | J7: Alta | K7: Baixa | L7: Peso em dados, integrações e analytics
A8: COL | B8: Colaboradores / Meu Time | C8: =COUNTIF('02_Inventario_Paginas'!$B$6:$B$200,A8) | D8: =COUNTIFS('02_Inventario_Paginas'!$B$6:$B$200,A8,'02_Inventario_Paginas'!$G$6:$G$200,"Alta")+COUNTIFS('02_Inventario_Paginas'!$B$6:$B$200,A8,'02_Inventario_Paginas'!$G$6:$G$200,"Muito alta") | E8: 2 | F8: Média | G8: Alta | H8: Média | I8: Sim | J8: Alta | K8: Média | L8: Dados sensíveis e ciclos internos
A9: CAN | B9: Candidatos & Carreira | C9: =COUNTIF('02_Inventario_Paginas'!$B$6:$B$200,A9) | D9: =COUNTIFS('02_Inventario_Paginas'!$B$6:$B$200,A9,'02_Inventario_Paginas'!$G$6:$G$200,"Alta")+COUNTIFS('02_Inventario_Paginas'!$B$6:$B$200,A9,'02_Inventario_Paginas'!$G$6:$G$200,"Muito alta") | E9: 4 | F9: Muito alta | G9: Alta | H9: Alta | I9: Sim | J9: Alta | K9: Alta | L9: Marketplace, matching e alto volume
A10: FOR | B10: Fornecedores & Negócios | C10: =COUNTIF('02_Inventario_Paginas'!$B$6:$B$200,A10) | D10: =COUNTIFS('02_Inventario_Paginas'!$B$6:$B$200,A10,'02_Inventario_Paginas'!$G$6:$G$200,"Alta")+COUNTIFS('02_Inventario_Paginas'!$B$6:$B$200,A10,'02_Inventario_Paginas'!$G$6:$G$200,"Muito alta") | E10: 2 | F10: Muito alta | G10: Alta | H10: Alta | I10: Responsivo | J10: Alta | K10: Alta | L10: B2B, documentos e negociação
A11: ACA | B11: Acadêmico / Universidades | C11: =COUNTIF('02_Inventario_Paginas'!$B$6:$B$200,A11) | D11: =COUNTIFS('02_Inventario_Paginas'!$B$6:$B$200,A11,'02_Inventario_Paginas'!$G$6:$G$200,"Alta")+COUNTIFS('02_Inventario_Paginas'!$B$6:$B$200,A11,'02_Inventario_Paginas'!$G$6:$G$200,"Muito alta") | E11: 3 | F11: Alta | G11: Alta | H11: Média | I11: Sim | J11: Alta | K11: Média | L11: Entidades acadêmicas e matching
A12: EVT | B12: Eventos | C12: =COUNTIF('02_Inventario_Paginas'!$B$6:$B$200,A12) | D12: =COUNTIFS('02_Inventario_Paginas'!$B$6:$B$200,A12,'02_Inventario_Paginas'!$G$6:$G$200,"Alta")+COUNTIFS('02_Inventario_Paginas'!$B$6:$B$200,A12,'02_Inventario_Paginas'!$G$6:$G$200,"Muito alta") | E12: 5 | F12: Alta | G12: Muito alta | H12: Alta | I12: Sim | J12: Muito alta | K12: Muito alta | L12: Tempo real, pesquisa e operação
A13: COM | B13: Comunidades / Eu & Eu / Cultura | C13: =COUNTIF('02_Inventario_Paginas'!$B$6:$B$200,A13) | D13: =COUNTIFS('02_Inventario_Paginas'!$B$6:$B$200,A13,'02_Inventario_Paginas'!$G$6:$G$200,"Alta")+COUNTIFS('02_Inventario_Paginas'!$B$6:$B$200,A13,'02_Inventario_Paginas'!$G$6:$G$200,"Muito alta") | E13: 4 | F13: Média | G13: Média | H13: Alta | I13: Sim | J13: Alta | K13: Alta | L13: B2C e engajamento
A14: CUST | B14: Clientes & Receita | C14: =COUNTIF('02_Inventario_Paginas'!$B$6:$B$200,A14) | D14: =COUNTIFS('02_Inventario_Paginas'!$B$6:$B$200,A14,'02_Inventario_Paginas'!$G$6:$G$200,"Alta")+COUNTIFS('02_Inventario_Paginas'!$B$6:$B$200,A14,'02_Inventario_Paginas'!$G$6:$G$200,"Muito alta") | E14: 2 | F14: Alta | G14: Muito alta | H14: Baixa | I14: Não | J14: Alta | K14: Baixa | L14: CRM/NPS/churn; alimenta HUB Impact.

Sheet 08_Premissas_Custos
A1: PREMISSAS PARA DIMENSIONAMENTO DE CUSTO
A3: Premissas iniciais editáveis. Não são orçamento de fornecedor: servem para transformar as 111 telas do escopo em uma primeira ordem de grandeza e depois calibrar com cotações reais.
A5: Complexidade da tela | B5: Multiplicador | C5: Uso | E5: Premissa geral | F5: Valor
A6: Baixa | B6: 0.65 | C6: Tela simples / leitura / formulário básico | E6: Contingência desenvolvimento | F6: 0.15
A7: Média | B7: 1 | C7: Fluxo padrão | E7: Gestão/arquitetura sobre build | F7: 0.12
A8: Alta | B8: 1.55 | C8: Regras, integrações ou visualizações complexas | E8: Meses de construção | F8: 9
A9: Muito alta | B9: 2.2 | C9: Matching, analytics avançado, simulação ou lógica intensa | E9: Meses de operação/ano | F9: 12
E10: Fator Fase 2 vs. MVP | F10: 0.9
E11: Reuso parcial de tela | F11: 0.55
A12: Disciplina | B12: Horas base / tela média | C12: Rate R$/h | D12: Mensalidade base R$ | E12: Driver mensal | F12: Observação
A13: UX/UI | B13: 22 | C13: 180 | D13: 0 | E13: Build | F13: Pesquisa, fluxo, wireframe, design e handoff
A14: Front-end | B14: 48 | C14: 220 | D14: 0 | E14: Build | F14: Web responsivo; mobile dedicado é driver adicional
A15: Back-end | B15: 54 | C15: 240 | D15: 0 | E15: Build | F15: APIs, regras e persistência
A16: Dados/BI | B16: 18 | C16: 260 | D16: 0 | E16: Build | F16: Modelagem, indicadores e pipelines leves
A17: IA/Matching | B17: 10 | C17: 320 | D17: 0 | E17: Build | F17: Aplicado apenas quando a tela tem driver de IA
A18: QA | B18: 20 | C18: 170 | D18: 0 | E18: Build | F18: Testes funcionais, regressão e automação gradual
A19: DevOps | B19: 8 | C19: 260 | D19: 0 | E19: Build | F19: CI/CD, ambientes e observabilidade
A20: Segurança | B20: 6 | C20: 320 | D20: 0 | E20: Build | F20: Threat modeling, hardening e revisão
A23: Custo mensal recorrente | B23: Base R$/mês | C23: Escala | D23: Observação
A24: Cloud / infraestrutura | B24: 18000 | C24: 1 | D24: Ambientes, banco, storage, observabilidade; recalibrar por volume
A25: Dados / pipelines / BI | B25: 14000 | C25: 1 | D25: Orquestração, processamento e monitoramento
A26: IA / modelos / APIs | B26: 12000 | C26: 1 | D26: Uso variável; depende de volume e arquitetura
A27: DevOps / SRE | B27: 22000 | C27: 1 | D27: Sustentação de plataforma
A28: Segurança / compliance | B28: 14000 | C28: 1 | D28: Monitoramento, scans, LGPD e auditoria
A29: QA / releases | B29: 16000 | C29: 1 | D29: Regressão e qualidade contínua
A30: Produto / operação técnica | B30: 28000 | C30: 1 | D30: Gestão de backlog, incidentes e evolução
A31: Suporte / CS técnico | B31: 18000 | C31: 1 | D31: Atendimento B2B e operação
A33: MVP+1: custo integral (fator 1, como MVP) — escopo near-term alinhado à Tecnica. Desconto de 0,9 aplica-se apenas a Fase 2. | E33: Fase Tecnica | F33: MVP / MVP+1 / Fase 2 + roadmap F0/MVP1..3

Sheet 09_Estimativa_96_Telas
A1: ESTIMATIVA DE BUILD POR TELA — 111 TELAS
A3: Horas são calculadas a partir da complexidade, disciplina e drivers específicos. A coluna 'Componente compartilhado' evita duplicar custo quando a mesma capacidade é reutilizada entre verticais.
A5: ID | B5: Código | C5: Frente | D5: Tela | E5: Fase | F5: Complexidade | G5: Componente compartilhado | H5: Reuso % | I5: Driver IA | J5: Driver Dados | K5: Driver Segurança | L5: Driver Mobile | M5: Mult. complex. | N5: UX h | O5: Front h | P5: Back h | Q5: Dados h | R5: IA h | S5: QA h | T5: DevOps h | U5: Segurança h | V5: Horas brutas | W5: Horas líquidas | X5: Custo build R$ | Y5: Gestão/arquitetura R$ | Z5: Contingência R$ | AA5: CAPEX tela R$ | AB5: Observação
A6: 1 | B6: CORE | C6: Core / Plataforma | D6: Login / SSO | E6: MVP | F6: Baixa | G6: CORE compartilhado | H6: 0.8 | I6: Não | J6: Não | K6: Sim | L6: Não | M6: =IF(F6="Baixa",'08_Premissas_Custos'!$B$6,IF(F6="Média",'08_Premissas_Custos'!$B$7,IF(F6="Alta",'08_Premissas_Custos'!$B$8,'08_Premissas_Custos'!$B$9))) | N6: ='08_Premissas_Custos'!$B$13*M6 | O6: ='08_Premissas_Custos'!$B$14*M6*(1+IF(L6="Sim",0.25,0)) | P6: ='08_Premissas_Custos'!$B$15*M6*(1+IF(I6="Sim",0.20,0)+IF(K6="Sim",0.15,0)) | Q6: ='08_Premissas_Custos'!$B$16*M6*IF(J6="Sim",1.6,0.55) | R6: ='08_Premissas_Custos'!$B$17*M6*IF(I6="Sim",1.8,0.15) | S6: ='08_Premissas_Custos'!$B$18*M6*(1+IF(I6="Sim",0.15)+IF(L6="Sim",0.10)) | T6: ='08_Premissas_Custos'!$B$19*M6*(1+IF(J6="Sim",0.15)) | U6: ='08_Premissas_Custos'!$B$20*M6*IF(K6="Sim",1.8,0.7) | V6: =SUM(N6:U6) | W6: =V6*(1-H6)*IF(E6="Fase 2",'08_Premissas_Custos'!$F$10,1) | X6: =(N6*'08_Premissas_Custos'!$C$13+O6*'08_Premissas_Custos'!$C$14+P6*'08_Premissas_Custos'!$C$15+Q6*'08_Premissas_Custos'!$C$16+R6*'08_Premissas_Custos'!$C$17+S6*'08_Premissas_Custos'!$C$18+T6*'08_Premissas_Custos'!$C$19+U6*'08_Premissas_Custos'!$C$20)*(1-H6)*IF(E6="Fase 2",'08_Premissas_Custos'!$F$10,1) | Y6: =X6*'08_Premissas_Custos'!$F$7 | Z6: =(X6+Y6)*'08_Premissas_Custos'!$F$6 | AA6: =SUM(X6:Z6) | AB6: Autenticação
A7: 2 | B7: CORE | C7: Core / Plataforma | D7: Cadastro / onboarding | E7: MVP | F7: Média | G7: CORE compartilhado | H7: 0.8 | I7: Não | J7: Não | K7: Sim | L7: Sim | M7: =IF(F7="Baixa",'08_Premissas_Custos'!$B$6,IF(F7="Média",'08_Premissas_Custos'!$B$7,IF(F7="Alta",'08_Premissas_Custos'!$B$8,'08_Premissas_Custos'!$B$9))) | N7: ='08_Premissas_Custos'!$B$13*M7 | O7: ='08_Premissas_Custos'!$B$14*M7*(1+IF(L7="Sim",0.25,0)) | P7: ='08_Premissas_Custos'!$B$15*M7*(1+IF(I7="Sim",0.20,0)+IF(K7="Sim",0.15,0)) | Q7: ='08_Premissas_Custos'!$B$16*M7*IF(J7="Sim",1.6,0.55) | R7: ='08_Premissas_Custos'!$B$17*M7*IF(I7="Sim",1.8,0.15) | S7: ='08_Premissas_Custos'!$B$18*M7*(1+IF(I7="Sim",0.15)+IF(L7="Sim",0.10)) | T7: ='08_Premissas_Custos'!$B$19*M7*(1+IF(J7="Sim",0.15)) | U7: ='08_Premissas_Custos'!$B$20*M7*IF(K7="Sim",1.8,0.7) | V7: =SUM(N7:U7) | W7: =V7*(1-H7)*IF(E7="Fase 2",'08_Premissas_Custos'!$F$10,1) | X7: =(N7*'08_Premissas_Custos'!$C$13+O7*'08_Premissas_Custos'!$C$14+P7*'08_Premissas_Custos'!$C$15+Q7*'08_Premissas_Custos'!$C$16+R7*'08_Premissas_Custos'!$C$17+S7*'08_Premissas_Custos'!$C$18+T7*'08_Premissas_Custos'!$C$19+U7*'08_Premissas_Custos'!$C$20)*(1-H7)*IF(E7="Fase 2",'08_Premissas_Custos'!$F$10,1) | Y7: =X7*'08_Premissas_Custos'!$F$7 | Z7: =(X7+Y7)*'08_Premissas_Custos'!$F$6 | AA7: =SUM(X7:Z7) | AB7: Entrada por tipo
A8: 3 | B8: CORE | C8: Core / Plataforma | D8: Perfis e organizações | E8: MVP | F8: Média | G8: CORE compartilhado | H8: 0.8 | I8: Não | J8: Não | K8: Sim | L8: Não | M8: =IF(F8="Baixa",'08_Premissas_Custos'!$B$6,IF(F8="Média",'08_Premissas_Custos'!$B$7,IF(F8="Alta",'08_Premissas_Custos'!$B$8,'08_Premissas_Custos'!$B$9))) | N8: ='08_Premissas_Custos'!$B$13*M8 | O8: ='08_Premissas_Custos'!$B$14*M8*(1+IF(L8="Sim",0.25,0)) | P8: ='08_Premissas_Custos'!$B$15*M8*(1+IF(I8="Sim",0.20,0)+IF(K8="Sim",0.15,0)) | Q8: ='08_Premissas_Custos'!$B$16*M8*IF(J8="Sim",1.6,0.55) | R8: ='08_Premissas_Custos'!$B$17*M8*IF(I8="Sim",1.8,0.15) | S8: ='08_Premissas_Custos'!$B$18*M8*(1+IF(I8="Sim",0.15)+IF(L8="Sim",0.10)) | T8: ='08_Premissas_Custos'!$B$19*M8*(1+IF(J8="Sim",0.15)) | U8: ='08_Premissas_Custos'!$B$20*M8*IF(K8="Sim",1.8,0.7) | V8: =SUM(N8:U8) | W8: =V8*(1-H8)*IF(E8="Fase 2",'08_Premissas_Custos'!$F$10,1) | X8: =(N8*'08_Premissas_Custos'!$C$13+O8*'08_Premissas_Custos'!$C$14+P8*'08_Premissas_Custos'!$C$15+Q8*'08_Premissas_Custos'!$C$16+R8*'08_Premissas_Custos'!$C$17+S8*'08_Premissas_Custos'!$C$18+T8*'08_Premissas_Custos'!$C$19+U8*'08_Premissas_Custos'!$C$20)*(1-H8)*IF(E8="Fase 2",'08_Premissas_Custos'!$F$10,1) | Y8: =X8*'08_Premissas_Custos'!$F$7 | Z8: =(X8+Y8)*'08_Premissas_Custos'!$F$6 | AA8: =SUM(X8:Z8) | AB8: Entidades
A9: 4 | B9: CORE | C9: Core / Plataforma | D9: Papéis e permissões | E9: MVP | F9: Alta | G9: CORE compartilhado | H9: 0.8 | I9: Não | J9: Não | K9: Sim | L9: Não | M9: =IF(F9="Baixa",'08_Premissas_Custos'!$B$6,IF(F9="Média",'08_Premissas_Custos'!$B$7,IF(F9="Alta",'08_Premissas_Custos'!$B$8,'08_Premissas_Custos'!$B$9))) | N9: ='08_Premissas_Custos'!$B$13*M9 | O9: ='08_Premissas_Custos'!$B$14*M9*(1+IF(L9="Sim",0.25,0)) | P9: ='08_Premissas_Custos'!$B$15*M9*(1+IF(I9="Sim",0.20,0)+IF(K9="Sim",0.15,0)) | Q9: ='08_Premissas_Custos'!$B$16*M9*IF(J9="Sim",1.6,0.55) | R9: ='08_Premissas_Custos'!$B$17*M9*IF(I9="Sim",1.8,0.15) | S9: ='08_Premissas_Custos'!$B$18*M9*(1+IF(I9="Sim",0.15)+IF(L9="Sim",0.10)) | T9: ='08_Premissas_Custos'!$B$19*M9*(1+IF(J9="Sim",0.15)) | U9: ='08_Premissas_Custos'!$B$20*M9*IF(K9="Sim",1.8,0.7) | V9: =SUM(N9:U9) | W9: =V9*(1-H9)*IF(E9="Fase 2",'08_Premissas_Custos'!$F$10,1) | X9: =(N9*'08_Premissas_Custos'!$C$13+O9*'08_Premissas_Custos'!$C$14+P9*'08_Premissas_Custos'!$C$15+Q9*'08_Premissas_Custos'!$C$16+R9*'08_Premissas_Custos'!$C$17+S9*'08_Premissas_Custos'!$C$18+T9*'08_Premissas_Custos'!$C$19+U9*'08_Premissas_Custos'!$C$20)*(1-H9)*IF(E9="Fase 2",'08_Premissas_Custos'!$F$10,1) | Y9: =X9*'08_Premissas_Custos'!$F$7 | Z9: =(X9+Y9)*'08_Premissas_Custos'!$F$6 | AA9: =SUM(X9:Z9) | AB9: RBAC
A10: 5 | B10: CORE | C10: Core / Plataforma | D10: Consentimentos / LGPD | E10: MVP | F10: Alta | G10: CORE compartilhado | H10: 0.8 | I10: Não | J10: Não | K10: Sim | L10: Não | M10: =IF(F10="Baixa",'08_Premissas_Custos'!$B$6,IF(F10="Média",'08_Premissas_Custos'!$B$7,IF(F10="Alta",'08_Premissas_Custos'!$B$8,'08_Premissas_Custos'!$B$9))) | N10: ='08_Premissas_Custos'!$B$13*M10 | O10: ='08_Premissas_Custos'!$B$14*M10*(1+IF(L10="Sim",0.25,0)) | P10: ='08_Premissas_Custos'!$B$15*M10*(1+IF(I10="Sim",0.20,0)+IF(K10="Sim",0.15,0)) | Q10: ='08_Premissas_Custos'!$B$16*M10*IF(J10="Sim",1.6,0.55) | R10: ='08_Premissas_Custos'!$B$17*M10*IF(I10="Sim",1.8,0.15) | S10: ='08_Premissas_Custos'!$B$18*M10*(1+IF(I10="Sim",0.15)+IF(L10="Sim",0.10)) | T10: ='08_Premissas_Custos'!$B$19*M10*(1+IF(J10="Sim",0.15)) | U10: ='08_Premissas_Custos'!$B$20*M10*IF(K10="Sim",1.8,0.7) | V10: =SUM(N10:U10) | W10: =V10*(1-H10)*IF(E10="Fase 2",'08_Premissas_Custos'!$F$10,1) | X10: =(N10*'08_Premissas_Custos'!$C$13+O10*'08_Premissas_Custos'!$C$14+P10*'08_Premissas_Custos'!$C$15+Q10*'08_Premissas_Custos'!$C$16+R10*'08_Premissas_Custos'!$C$17+S10*'08_Premissas_Custos'!$C$18+T10*'08_Premissas_Custos'!$C$19+U10*'08_Premissas_Custos'!$C$20)*(1-H10)*IF(E10="Fase 2",'08_Premissas_Custos'!$F$10,1) | Y10: =X10*'08_Premissas_Custos'!$F$7 | Z10: =(X10+Y10)*'08_Premissas_Custos'!$F$6 | AA10: =SUM(X10:Z10) | AB10: Privacidade
A11: 6 | B11: CORE | C11: Core / Plataforma | D11: Central de integrações | E11: MVP | F11: Alta | G11: CORE compartilhado | H11: 0.8 | I11: Não | J11: Não | K11: Sim | L11: Não | M11: =IF(F11="Baixa",'08_Premissas_Custos'!$B$6,IF(F11="Média",'08_Premissas_Custos'!$B$7,IF(F11="Alta",'08_Premissas_Custos'!$B$8,'08_Premissas_Custos'!$B$9))) | N11: ='08_Premissas_Custos'!$B$13*M11 | O11: ='08_Premissas_Custos'!$B$14*M11*(1+IF(L11="Sim",0.25,0)) | P11: ='08_Premissas_Custos'!$B$15*M11*(1+IF(I11="Sim",0.20,0)+IF(K11="Sim",0.15,0)) | Q11: ='08_Premissas_Custos'!$B$16*M11*IF(J11="Sim",1.6,0.55) | R11: ='08_Premissas_Custos'!$B$17*M11*IF(I11="Sim",1.8,0.15) | S11: ='08_Premissas_Custos'!$B$18*M11*(1+IF(I11="Sim",0.15)+IF(L11="Sim",0.10)) | T11: ='08_Premissas_Custos'!$B$19*M11*(1+IF(J11="Sim",0.15)) | U11: ='08_Premissas_Custos'!$B$20*M11*IF(K11="Sim",1.8,0.7) | V11: =SUM(N11:U11) | W11: =V11*(1-H11)*IF(E11="Fase 2",'08_Premissas_Custos'!$F$10,1) | X11: =(N11*'08_Premissas_Custos'!$C$13+O11*'08_Premissas_Custos'!$C$14+P11*'08_Premissas_Custos'!$C$15+Q11*'08_Premissas_Custos'!$C$16+R11*'08_Premissas_Custos'!$C$17+S11*'08_Premissas_Custos'!$C$18+T11*'08_Premissas_Custos'!$C$19+U11*'08_Premissas_Custos'!$C$20)*(1-H11)*IF(E11="Fase 2",'08_Premissas_Custos'!$F$10,1) | Y11: =X11*'08_Premissas_Custos'!$F$7 | Z11: =(X11+Y11)*'08_Premissas_Custos'!$F$6 | AA11: =SUM(X11:Z11) | AB11: APIs/RHIS/ERP/CRM/LMS
A12: 7 | B12: CORE | C12: Core / Plataforma | D12: Notificações | E12: MVP | F12: Média | G12: CORE compartilhado | H12: 0.8 | I12: Não | J12: Não | K12: Sim | L12: Sim | M12: =IF(F12="Baixa",'08_Premissas_Custos'!$B$6,IF(F12="Média",'08_Premissas_Custos'!$B$7,IF(F12="Alta",'08_Premissas_Custos'!$B$8,'08_Premissas_Custos'!$B$9))) | N12: ='08_Premissas_Custos'!$B$13*M12 | O12: ='08_Premissas_Custos'!$B$14*M12*(1+IF(L12="Sim",0.25,0)) | P12: ='08_Premissas_Custos'!$B$15*M12*(1+IF(I12="Sim",0.20,0)+IF(K12="Sim",0.15,0)) | Q12: ='08_Premissas_Custos'!$B$16*M12*IF(J12="Sim",1.6,0.55) | R12: ='08_Premissas_Custos'!$B$17*M12*IF(I12="Sim",1.8,0.15) | S12: ='08_Premissas_Custos'!$B$18*M12*(1+IF(I12="Sim",0.15)+IF(L12="Sim",0.10)) | T12: ='08_Premissas_Custos'!$B$19*M12*(1+IF(J12="Sim",0.15)) | U12: ='08_Premissas_Custos'!$B$20*M12*IF(K12="Sim",1.8,0.7) | V12: =SUM(N12:U12) | W12: =V12*(1-H12)*IF(E12="Fase 2",'08_Premissas_Custos'!$F$10,1) | X12: =(N12*'08_Premissas_Custos'!$C$13+O12*'08_Premissas_Custos'!$C$14+P12*'08_Premissas_Custos'!$C$15+Q12*'08_Premissas_Custos'!$C$16+R12*'08_Premissas_Custos'!$C$17+S12*'08_Premissas_Custos'!$C$18+T12*'08_Premissas_Custos'!$C$19+U12*'08_Premissas_Custos'!$C$20)*(1-H12)*IF(E12="Fase 2",'08_Premissas_Custos'!$F$10,1) | Y12: =X12*'08_Premissas_Custos'!$F$7 | Z12: =(X12+Y12)*'08_Premissas_Custos'!$F$6 | AA12: =SUM(X12:Z12) | AB12: Gatilhos
A13: 8 | B13: CORE | C13: Core / Plataforma | D13: Mensagens | E13: Fase 2 | F13: Alta | G13: CORE compartilhado | H13: 0.8 | I13: Não | J13: Não | K13: Sim | L13: Sim | M13: =IF(F13="Baixa",'08_Premissas_Custos'!$B$6,IF(F13="Média",'08_Premissas_Custos'!$B$7,IF(F13="Alta",'08_Premissas_Custos'!$B$8,'08_Premissas_Custos'!$B$9))) | N13: ='08_Premissas_Custos'!$B$13*M13 | O13: ='08_Premissas_Custos'!$B$14*M13*(1+IF(L13="Sim",0.25,0)) | P13: ='08_Premissas_Custos'!$B$15*M13*(1+IF(I13="Sim",0.20,0)+IF(K13="Sim",0.15,0)) | Q13: ='08_Premissas_Custos'!$B$16*M13*IF(J13="Sim",1.6,0.55) | R13: ='08_Premissas_Custos'!$B$17*M13*IF(I13="Sim",1.8,0.15) | S13: ='08_Premissas_Custos'!$B$18*M13*(1+IF(I13="Sim",0.15)+IF(L13="Sim",0.10)) | T13: ='08_Premissas_Custos'!$B$19*M13*(1+IF(J13="Sim",0.15)) | U13: ='08_Premissas_Custos'!$B$20*M13*IF(K13="Sim",1.8,0.7) | V13: =SUM(N13:U13) | W13: =V13*(1-H13)*IF(E13="Fase 2",'08_Premissas_Custos'!$F$10,1) | X13: =(N13*'08_Premissas_Custos'!$C$13+O13*'08_Premissas_Custos'!$C$14+P13*'08_Premissas_Custos'!$C$15+Q13*'08_Premissas_Custos'!$C$16+R13*'08_Premissas_Custos'!$C$17+S13*'08_Premissas_Custos'!$C$18+T13*'08_Premissas_Custos'!$C$19+U13*'08_Premissas_Custos'!$C$20)*(1-H13)*IF(E13="Fase 2",'08_Premissas_Custos'!$F$10,1) | Y13: =X13*'08_Premissas_Custos'!$F$7 | Z13: =(X13+Y13)*'08_Premissas_Custos'!$F$6 | AA13: =SUM(X13:Z13) | AB13: Conversas
A14: 9 | B14: CORE | C14: Core / Plataforma | D14: Busca global | E14: Fase 2 | F14: Média | G14: CORE compartilhado | H14: 0.8 | I14: Não | J14: Não | K14: Sim | L14: Não | M14: =IF(F14="Baixa",'08_Premissas_Custos'!$B$6,IF(F14="Média",'08_Premissas_Custos'!$B$7,IF(F14="Alta",'08_Premissas_Custos'!$B$8,'08_Premissas_Custos'!$B$9))) | N14: ='08_Premissas_Custos'!$B$13*M14 | O14: ='08_Premissas_Custos'!$B$14*M14*(1+IF(L14="Sim",0.25,0)) | P14: ='08_Premissas_Custos'!$B$15*M14*(1+IF(I14="Sim",0.20,0)+IF(K14="Sim",0.15,0)) | Q14: ='08_Premissas_Custos'!$B$16*M14*IF(J14="Sim",1.6,0.55) | R14: ='08_Premissas_Custos'!$B$17*M14*IF(I14="Sim",1.8,0.15) | S14: ='08_Premissas_Custos'!$B$18*M14*(1+IF(I14="Sim",0.15)+IF(L14="Sim",0.10)) | T14: ='08_Premissas_Custos'!$B$19*M14*(1+IF(J14="Sim",0.15)) | U14: ='08_Premissas_Custos'!$B$20*M14*IF(K14="Sim",1.8,0.7) | V14: =SUM(N14:U14) | W14: =V14*(1-H14)*IF(E14="Fase 2",'08_Premissas_Custos'!$F$10,1) | X14: =(N14*'08_Premissas_Custos'!$C$13+O14*'08_Premissas_Custos'!$C$14+P14*'08_Premissas_Custos'!$C$15+Q14*'08_Premissas_Custos'!$C$16+R14*'08_Premissas_Custos'!$C$17+S14*'08_Premissas_Custos'!$C$18+T14*'08_Premissas_Custos'!$C$19+U14*'08_Premissas_Custos'!$C$20)*(1-H14)*IF(E14="Fase 2",'08_Premissas_Custos'!$F$10,1) | Y14: =X14*'08_Premissas_Custos'!$F$7 | Z14: =(X14+Y14)*'08_Premissas_Custos'!$F$6 | AA14: =SUM(X14:Z14) | AB14: Busca
A15: 10 | B15: CORE | C15: Core / Plataforma | D15: Analytics de uso | E15: MVP | F15: Média | G15: CORE compartilhado | H15: 0.8 | I15: Não | J15: Sim | K15: Sim | L15: Não | M15: =IF(F15="Baixa",'08_Premissas_Custos'!$B$6,IF(F15="Média",'08_Premissas_Custos'!$B$7,IF(F15="Alta",'08_Premissas_Custos'!$B$8,'08_Premissas_Custos'!$B$9))) | N15: ='08_Premissas_Custos'!$B$13*M15 | O15: ='08_Premissas_Custos'!$B$14*M15*(1+IF(L15="Sim",0.25,0)) | P15: ='08_Premissas_Custos'!$B$15*M15*(1+IF(I15="Sim",0.20,0)+IF(K15="Sim",0.15,0)) | Q15: ='08_Premissas_Custos'!$B$16*M15*IF(J15="Sim",1.6,0.55) | R15: ='08_Premissas_Custos'!$B$17*M15*IF(I15="Sim",1.8,0.15) | S15: ='08_Premissas_Custos'!$B$18*M15*(1+IF(I15="Sim",0.15)+IF(L15="Sim",0.10)) | T15: ='08_Premissas_Custos'!$B$19*M15*(1+IF(J15="Sim",0.15)) | U15: ='08_Premissas_Custos'!$B$20*M15*IF(K15="Sim",1.8,0.7) | V15: =SUM(N15:U15) | W15: =V15*(1-H15)*IF(E15="Fase 2",'08_Premissas_Custos'!$F$10,1) | X15: =(N15*'08_Premissas_Custos'!$C$13+O15*'08_Premissas_Custos'!$C$14+P15*'08_Premissas_Custos'!$C$15+Q15*'08_Premissas_Custos'!$C$16+R15*'08_Premissas_Custos'!$C$17+S15*'08_Premissas_Custos'!$C$18+T15*'08_Premissas_Custos'!$C$19+U15*'08_Premissas_Custos'!$C$20)*(1-H15)*IF(E15="Fase 2",'08_Premissas_Custos'!$F$10,1) | Y15: =X15*'08_Premissas_Custos'!$F$7 | Z15: =(X15+Y15)*'08_Premissas_Custos'!$F$6 | AA15: =SUM(X15:Z15) | AB15: Adoção
A16: 11 | B16: CORE | C16: Core / Plataforma | D16: Administração | E16: MVP | F16: Alta | G16: CORE compartilhado | H16: 0.8 | I16: Não | J16: Não | K16: Sim | L16: Não | M16: =IF(F16="Baixa",'08_Premissas_Custos'!$B$6,IF(F16="Média",'08_Premissas_Custos'!$B$7,IF(F16="Alta",'08_Premissas_Custos'!$B$8,'08_Premissas_Custos'!$B$9))) | N16: ='08_Premissas_Custos'!$B$13*M16 | O16: ='08_Premissas_Custos'!$B$14*M16*(1+IF(L16="Sim",0.25,0)) | P16: ='08_Premissas_Custos'!$B$15*M16*(1+IF(I16="Sim",0.20,0)+IF(K16="Sim",0.15,0)) | Q16: ='08_Premissas_Custos'!$B$16*M16*IF(J16="Sim",1.6,0.55) | R16: ='08_Premissas_Custos'!$B$17*M16*IF(I16="Sim",1.8,0.15) | S16: ='08_Premissas_Custos'!$B$18*M16*(1+IF(I16="Sim",0.15)+IF(L16="Sim",0.10)) | T16: ='08_Premissas_Custos'!$B$19*M16*(1+IF(J16="Sim",0.15)) | U16: ='08_Premissas_Custos'!$B$20*M16*IF(K16="Sim",1.8,0.7) | V16: =SUM(N16:U16) | W16: =V16*(1-H16)*IF(E16="Fase 2",'08_Premissas_Custos'!$F$10,1) | X16: =(N16*'08_Premissas_Custos'!$C$13+O16*'08_Premissas_Custos'!$C$14+P16*'08_Premissas_Custos'!$C$15+Q16*'08_Premissas_Custos'!$C$16+R16*'08_Premissas_Custos'!$C$17+S16*'08_Premissas_Custos'!$C$18+T16*'08_Premissas_Custos'!$C$19+U16*'08_Premissas_Custos'!$C$20)*(1-H16)*IF(E16="Fase 2",'08_Premissas_Custos'!$F$10,1) | Y16: =X16*'08_Premissas_Custos'!$F$7 | Z16: =(X16+Y16)*'08_Premissas_Custos'!$F$6 | AA16: =SUM(X16:Z16) | AB16: Configurações
A17: 12 | B17: CORE | C17: Core / Plataforma | D17: Auditoria e logs | E17: MVP | F17: Alta | G17: CORE compartilhado | H17: 0.8 | I17: Não | J17: Não | K17: Sim | L17: Não | M17: =IF(F17="Baixa",'08_Premissas_Custos'!$B$6,IF(F17="Média",'08_Premissas_Custos'!$B$7,IF(F17="Alta",'08_Premissas_Custos'!$B$8,'08_Premissas_Custos'!$B$9))) | N17: ='08_Premissas_Custos'!$B$13*M17 | O17: ='08_Premissas_Custos'!$B$14*M17*(1+IF(L17="Sim",0.25,0)) | P17: ='08_Premissas_Custos'!$B$15*M17*(1+IF(I17="Sim",0.20,0)+IF(K17="Sim",0.15,0)) | Q17: ='08_Premissas_Custos'!$B$16*M17*IF(J17="Sim",1.6,0.55) | R17: ='08_Premissas_Custos'!$B$17*M17*IF(I17="Sim",1.8,0.15) | S17: ='08_Premissas_Custos'!$B$18*M17*(1+IF(I17="Sim",0.15)+IF(L17="Sim",0.10)) | T17: ='08_Premissas_Custos'!$B$19*M17*(1+IF(J17="Sim",0.15)) | U17: ='08_Premissas_Custos'!$B$20*M17*IF(K17="Sim",1.8,0.7) | V17: =SUM(N17:U17) | W17: =V17*(1-H17)*IF(E17="Fase 2",'08_Premissas_Custos'!$F$10,1) | X17: =(N17*'08_Premissas_Custos'!$C$13+O17*'08_Premissas_Custos'!$C$14+P17*'08_Premissas_Custos'!$C$15+Q17*'08_Premissas_Custos'!$C$16+R17*'08_Premissas_Custos'!$C$17+S17*'08_Premissas_Custos'!$C$18+T17*'08_Premissas_Custos'!$C$19+U17*'08_Premissas_Custos'!$C$20)*(1-H17)*IF(E17="Fase 2",'08_Premissas_Custos'!$F$10,1) | Y17: =X17*'08_Premissas_Custos'!$F$7 | Z17: =(X17+Y17)*'08_Premissas_Custos'!$F$6 | AA17: =SUM(X17:Z17) | AB17: Rastreabilidade
A18: 13 | B18: ED | C18: Estratégia & Dados | D18: Visão executiva | E18: MVP | F18: Alta | H18: 0 | I18: Não | J18: Sim | K18: Não | L18: Não | M18: =IF(F18="Baixa",'08_Premissas_Custos'!$B$6,IF(F18="Média",'08_Premissas_Custos'!$B$7,IF(F18="Alta",'08_Premissas_Custos'!$B$8,'08_Premissas_Custos'!$B$9))) | N18: ='08_Premissas_Custos'!$B$13*M18 | O18: ='08_Premissas_Custos'!$B$14*M18*(1+IF(L18="Sim",0.25,0)) | P18: ='08_Premissas_Custos'!$B$15*M18*(1+IF(I18="Sim",0.20,0)+IF(K18="Sim",0.15,0)) | Q18: ='08_Premissas_Custos'!$B$16*M18*IF(J18="Sim",1.6,0.55) | R18: ='08_Premissas_Custos'!$B$17*M18*IF(I18="Sim",1.8,0.15) | S18: ='08_Premissas_Custos'!$B$18*M18*(1+IF(I18="Sim",0.15)+IF(L18="Sim",0.10)) | T18: ='08_Premissas_Custos'!$B$19*M18*(1+IF(J18="Sim",0.15)) | U18: ='08_Premissas_Custos'!$B$20*M18*IF(K18="Sim",1.8,0.7) | V18: =SUM(N18:U18) | W18: =V18*(1-H18)*IF(E18="Fase 2",'08_Premissas_Custos'!$F$10,1) | X18: =(N18*'08_Premissas_Custos'!$C$13+O18*'08_Premissas_Custos'!$C$14+P18*'08_Premissas_Custos'!$C$15+Q18*'08_Premissas_Custos'!$C$16+R18*'08_Premissas_Custos'!$C$17+S18*'08_Premissas_Custos'!$C$18+T18*'08_Premissas_Custos'!$C$19+U18*'08_Premissas_Custos'!$C$20)*(1-H18)*IF(E18="Fase 2",'08_Premissas_Custos'!$F$10,1) | Y18: =X18*'08_Premissas_Custos'!$F$7 | Z18: =(X18+Y18)*'08_Premissas_Custos'!$F$6 | AA18: =SUM(X18:Z18) | AB18: KPIs pessoas x negócio
A19: 14 | B19: ED | C19: Estratégia & Dados | D19: Conectores de dados | E19: MVP | F19: Alta | H19: 0 | I19: Não | J19: Sim | K19: Não | L19: Não | M19: =IF(F19="Baixa",'08_Premissas_Custos'!$B$6,IF(F19="Média",'08_Premissas_Custos'!$B$7,IF(F19="Alta",'08_Premissas_Custos'!$B$8,'08_Premissas_Custos'!$B$9))) | N19: ='08_Premissas_Custos'!$B$13*M19 | O19: ='08_Premissas_Custos'!$B$14*M19*(1+IF(L19="Sim",0.25,0)) | P19: ='08_Premissas_Custos'!$B$15*M19*(1+IF(I19="Sim",0.20,0)+IF(K19="Sim",0.15,0)) | Q19: ='08_Premissas_Custos'!$B$16*M19*IF(J19="Sim",1.6,0.55) | R19: ='08_Premissas_Custos'!$B$17*M19*IF(I19="Sim",1.8,0.15) | S19: ='08_Premissas_Custos'!$B$18*M19*(1+IF(I19="Sim",0.15)+IF(L19="Sim",0.10)) | T19: ='08_Premissas_Custos'!$B$19*M19*(1+IF(J19="Sim",0.15)) | U19: ='08_Premissas_Custos'!$B$20*M19*IF(K19="Sim",1.8,0.7) | V19: =SUM(N19:U19) | W19: =V19*(1-H19)*IF(E19="Fase 2",'08_Premissas_Custos'!$F$10,1) | X19: =(N19*'08_Premissas_Custos'!$C$13+O19*'08_Premissas_Custos'!$C$14+P19*'08_Premissas_Custos'!$C$15+Q19*'08_Premissas_Custos'!$C$16+R19*'08_Premissas_Custos'!$C$17+S19*'08_Premissas_Custos'!$C$18+T19*'08_Premissas_Custos'!$C$19+U19*'08_Premissas_Custos'!$C$20)*(1-H19)*IF(E19="Fase 2",'08_Premissas_Custos'!$F$10,1) | Y19: =X19*'08_Premissas_Custos'!$F$7 | Z19: =(X19+Y19)*'08_Premissas_Custos'!$F$6 | AA19: =SUM(X19:Z19) | AB19: Dados existentes
A20: 15 | B20: ED | C20: Estratégia & Dados | D20: Mapeamento de indicadores | E20: MVP | F20: Alta | H20: 0 | I20: Não | J20: Sim | K20: Não | L20: Não | M20: =IF(F20="Baixa",'08_Premissas_Custos'!$B$6,IF(F20="Média",'08_Premissas_Custos'!$B$7,IF(F20="Alta",'08_Premissas_Custos'!$B$8,'08_Premissas_Custos'!$B$9))) | N20: ='08_Premissas_Custos'!$B$13*M20 | O20: ='08_Premissas_Custos'!$B$14*M20*(1+IF(L20="Sim",0.25,0)) | P20: ='08_Premissas_Custos'!$B$15*M20*(1+IF(I20="Sim",0.20,0)+IF(K20="Sim",0.15,0)) | Q20: ='08_Premissas_Custos'!$B$16*M20*IF(J20="Sim",1.6,0.55) | R20: ='08_Premissas_Custos'!$B$17*M20*IF(I20="Sim",1.8,0.15) | S20: ='08_Premissas_Custos'!$B$18*M20*(1+IF(I20="Sim",0.15)+IF(L20="Sim",0.10)) | T20: ='08_Premissas_Custos'!$B$19*M20*(1+IF(J20="Sim",0.15)) | U20: ='08_Premissas_Custos'!$B$20*M20*IF(K20="Sim",1.8,0.7) | V20: =SUM(N20:U20) | W20: =V20*(1-H20)*IF(E20="Fase 2",'08_Premissas_Custos'!$F$10,1) | X20: =(N20*'08_Premissas_Custos'!$C$13+O20*'08_Premissas_Custos'!$C$14+P20*'08_Premissas_Custos'!$C$15+Q20*'08_Premissas_Custos'!$C$16+R20*'08_Premissas_Custos'!$C$17+S20*'08_Premissas_Custos'!$C$18+T20*'08_Premissas_Custos'!$C$19+U20*'08_Premissas_Custos'!$C$20)*(1-H20)*IF(E20="Fase 2",'08_Premissas_Custos'!$F$10,1) | Y20: =X20*'08_Premissas_Custos'!$F$7 | Z20: =(X20+Y20)*'08_Premissas_Custos'!$F$6 | AA20: =SUM(X20:Z20) | AB20: Dicionário
A21: 16 | B21: ED | C21: Estratégia & Dados | D21: Diagnóstico | E21: MVP | F21: Alta | H21: 0 | I21: Não | J21: Sim | K21: Não | L21: Não | M21: =IF(F21="Baixa",'08_Premissas_Custos'!$B$6,IF(F21="Média",'08_Premissas_Custos'!$B$7,IF(F21="Alta",'08_Premissas_Custos'!$B$8,'08_Premissas_Custos'!$B$9))) | N21: ='08_Premissas_Custos'!$B$13*M21 | O21: ='08_Premissas_Custos'!$B$14*M21*(1+IF(L21="Sim",0.25,0)) | P21: ='08_Premissas_Custos'!$B$15*M21*(1+IF(I21="Sim",0.20,0)+IF(K21="Sim",0.15,0)) | Q21: ='08_Premissas_Custos'!$B$16*M21*IF(J21="Sim",1.6,0.55) | R21: ='08_Premissas_Custos'!$B$17*M21*IF(I21="Sim",1.8,0.15) | S21: ='08_Premissas_Custos'!$B$18*M21*(1+IF(I21="Sim",0.15)+IF(L21="Sim",0.10)) | T21: ='08_Premissas_Custos'!$B$19*M21*(1+IF(J21="Sim",0.15)) | U21: ='08_Premissas_Custos'!$B$20*M21*IF(K21="Sim",1.8,0.7) | V21: =SUM(N21:U21) | W21: =V21*(1-H21)*IF(E21="Fase 2",'08_Premissas_Custos'!$F$10,1) | X21: =(N21*'08_Premissas_Custos'!$C$13+O21*'08_Premissas_Custos'!$C$14+P21*'08_Premissas_Custos'!$C$15+Q21*'08_Premissas_Custos'!$C$16+R21*'08_Premissas_Custos'!$C$17+S21*'08_Premissas_Custos'!$C$18+T21*'08_Premissas_Custos'!$C$19+U21*'08_Premissas_Custos'!$C$20)*(1-H21)*IF(E21="Fase 2",'08_Premissas_Custos'!$F$10,1) | Y21: =X21*'08_Premissas_Custos'!$F$7 | Z21: =(X21+Y21)*'08_Premissas_Custos'!$F$6 | AA21: =SUM(X21:Z21) | AB21: Contexto
A22: 17 | B22: ED | C22: Estratégia & Dados | D22: Análises e correlações | E22: MVP | F22: Muito alta | H22: 0 | I22: Sim | J22: Sim | K22: Não | L22: Não | M22: =IF(F22="Baixa",'08_Premissas_Custos'!$B$6,IF(F22="Média",'08_Premissas_Custos'!$B$7,IF(F22="Alta",'08_Premissas_Custos'!$B$8,'08_Premissas_Custos'!$B$9))) | N22: ='08_Premissas_Custos'!$B$13*M22 | O22: ='08_Premissas_Custos'!$B$14*M22*(1+IF(L22="Sim",0.25,0)) | P22: ='08_Premissas_Custos'!$B$15*M22*(1+IF(I22="Sim",0.20,0)+IF(K22="Sim",0.15,0)) | Q22: ='08_Premissas_Custos'!$B$16*M22*IF(J22="Sim",1.6,0.55) | R22: ='08_Premissas_Custos'!$B$17*M22*IF(I22="Sim",1.8,0.15) | S22: ='08_Premissas_Custos'!$B$18*M22*(1+IF(I22="Sim",0.15)+IF(L22="Sim",0.10)) | T22: ='08_Premissas_Custos'!$B$19*M22*(1+IF(J22="Sim",0.15)) | U22: ='08_Premissas_Custos'!$B$20*M22*IF(K22="Sim",1.8,0.7) | V22: =SUM(N22:U22) | W22: =V22*(1-H22)*IF(E22="Fase 2",'08_Premissas_Custos'!$F$10,1) | X22: =(N22*'08_Premissas_Custos'!$C$13+O22*'08_Premissas_Custos'!$C$14+P22*'08_Premissas_Custos'!$C$15+Q22*'08_Premissas_Custos'!$C$16+R22*'08_Premissas_Custos'!$C$17+S22*'08_Premissas_Custos'!$C$18+T22*'08_Premissas_Custos'!$C$19+U22*'08_Premissas_Custos'!$C$20)*(1-H22)*IF(E22="Fase 2",'08_Premissas_Custos'!$F$10,1) | Y22: =X22*'08_Premissas_Custos'!$F$7 | Z22: =(X22+Y22)*'08_Premissas_Custos'!$F$6 | AA22: =SUM(X22:Z22) | AB22: Padrões
A23: 18 | B23: ED | C23: Estratégia & Dados | D23: Prioridades | E23: MVP | F23: Alta | H23: 0 | I23: Não | J23: Sim | K23: Não | L23: Não | M23: =IF(F23="Baixa",'08_Premissas_Custos'!$B$6,IF(F23="Média",'08_Premissas_Custos'!$B$7,IF(F23="Alta",'08_Premissas_Custos'!$B$8,'08_Premissas_Custos'!$B$9))) | N23: ='08_Premissas_Custos'!$B$13*M23 | O23: ='08_Premissas_Custos'!$B$14*M23*(1+IF(L23="Sim",0.25,0)) | P23: ='08_Premissas_Custos'!$B$15*M23*(1+IF(I23="Sim",0.20,0)+IF(K23="Sim",0.15,0)) | Q23: ='08_Premissas_Custos'!$B$16*M23*IF(J23="Sim",1.6,0.55) | R23: ='08_Premissas_Custos'!$B$17*M23*IF(I23="Sim",1.8,0.15) | S23: ='08_Premissas_Custos'!$B$18*M23*(1+IF(I23="Sim",0.15)+IF(L23="Sim",0.10)) | T23: ='08_Premissas_Custos'!$B$19*M23*(1+IF(J23="Sim",0.15)) | U23: ='08_Premissas_Custos'!$B$20*M23*IF(K23="Sim",1.8,0.7) | V23: =SUM(N23:U23) | W23: =V23*(1-H23)*IF(E23="Fase 2",'08_Premissas_Custos'!$F$10,1) | X23: =(N23*'08_Premissas_Custos'!$C$13+O23*'08_Premissas_Custos'!$C$14+P23*'08_Premissas_Custos'!$C$15+Q23*'08_Premissas_Custos'!$C$16+R23*'08_Premissas_Custos'!$C$17+S23*'08_Premissas_Custos'!$C$18+T23*'08_Premissas_Custos'!$C$19+U23*'08_Premissas_Custos'!$C$20)*(1-H23)*IF(E23="Fase 2",'08_Premissas_Custos'!$F$10,1) | Y23: =X23*'08_Premissas_Custos'!$F$7 | Z23: =(X23+Y23)*'08_Premissas_Custos'!$F$6 | AA23: =SUM(X23:Z23) | AB23: Riscos/oportunidades
A24: 19 | B24: ED | C24: Estratégia & Dados | D24: Planos de ação | E24: MVP | F24: Média | H24: 0 | I24: Não | J24: Sim | K24: Não | L24: Não | M24: =IF(F24="Baixa",'08_Premissas_Custos'!$B$6,IF(F24="Média",'08_Premissas_Custos'!$B$7,IF(F24="Alta",'08_Premissas_Custos'!$B$8,'08_Premissas_Custos'!$B$9))) | N24: ='08_Premissas_Custos'!$B$13*M24 | O24: ='08_Premissas_Custos'!$B$14*M24*(1+IF(L24="Sim",0.25,0)) | P24: ='08_Premissas_Custos'!$B$15*M24*(1+IF(I24="Sim",0.20,0)+IF(K24="Sim",0.15,0)) | Q24: ='08_Premissas_Custos'!$B$16*M24*IF(J24="Sim",1.6,0.55) | R24: ='08_Premissas_Custos'!$B$17*M24*IF(I24="Sim",1.8,0.15) | S24: ='08_Premissas_Custos'!$B$18*M24*(1+IF(I24="Sim",0.15)+IF(L24="Sim",0.10)) | T24: ='08_Premissas_Custos'!$B$19*M24*(1+IF(J24="Sim",0.15)) | U24: ='08_Premissas_Custos'!$B$20*M24*IF(K24="Sim",1.8,0.7) | V24: =SUM(N24:U24) | W24: =V24*(1-H24)*IF(E24="Fase 2",'08_Premissas_Custos'!$F$10,1) | X24: =(N24*'08_Premissas_Custos'!$C$13+O24*'08_Premissas_Custos'!$C$14+P24*'08_Premissas_Custos'!$C$15+Q24*'08_Premissas_Custos'!$C$16+R24*'08_Premissas_Custos'!$C$17+S24*'08_Premissas_Custos'!$C$18+T24*'08_Premissas_Custos'!$C$19+U24*'08_Premissas_Custos'!$C$20)*(1-H24)*IF(E24="Fase 2",'08_Premissas_Custos'!$F$10,1) | Y24: =X24*'08_Premissas_Custos'!$F$7 | Z24: =(X24+Y24)*'08_Premissas_Custos'!$F$6 | AA24: =SUM(X24:Z24) | AB24: Ações
A25: 20 | B25: ED | C25: Estratégia & Dados | D25: Cenários / simulações | E25: Fase 2 | F25: Muito alta | H25: 0 | I25: Sim | J25: Sim | K25: Não | L25: Não | M25: =IF(F25="Baixa",'08_Premissas_Custos'!$B$6,IF(F25="Média",'08_Premissas_Custos'!$B$7,IF(F25="Alta",'08_Premissas_Custos'!$B$8,'08_Premissas_Custos'!$B$9))) | N25: ='08_Premissas_Custos'!$B$13*M25 | O25: ='08_Premissas_Custos'!$B$14*M25*(1+IF(L25="Sim",0.25,0)) | P25: ='08_Premissas_Custos'!$B$15*M25*(1+IF(I25="Sim",0.20,0)+IF(K25="Sim",0.15,0)) | Q25: ='08_Premissas_Custos'!$B$16*M25*IF(J25="Sim",1.6,0.55) | R25: ='08_Premissas_Custos'!$B$17*M25*IF(I25="Sim",1.8,0.15) | S25: ='08_Premissas_Custos'!$B$18*M25*(1+IF(I25="Sim",0.15)+IF(L25="Sim",0.10)) | T25: ='08_Premissas_Custos'!$B$19*M25*(1+IF(J25="Sim",0.15)) | U25: ='08_Premissas_Custos'!$B$20*M25*IF(K25="Sim",1.8,0.7) | V25: =SUM(N25:U25) | W25: =V25*(1-H25)*IF(E25="Fase 2",'08_Premissas_Custos'!$F$10,1) | X25: =(N25*'08_Premissas_Custos'!$C$13+O25*'08_Premissas_Custos'!$C$14+P25*'08_Premissas_Custos'!$C$15+Q25*'08_Premissas_Custos'!$C$16+R25*'08_Premissas_Custos'!$C$17+S25*'08_Premissas_Custos'!$C$18+T25*'08_Premissas_Custos'!$C$19+U25*'08_Premissas_Custos'!$C$20)*(1-H25)*IF(E25="Fase 2",'08_Premissas_Custos'!$F$10,1) | Y25: =X25*'08_Premissas_Custos'!$F$7 | Z25: =(X25+Y25)*'08_Premissas_Custos'!$F$6 | AA25: =SUM(X25:Z25) | AB25: Projeções
A26: 21 | B26: ED | C26: Estratégia & Dados | D26: ROI / valor capturado | E26: MVP | F26: Alta | H26: 0 | I26: Não | J26: Sim | K26: Não | L26: Não | M26: =IF(F26="Baixa",'08_Premissas_Custos'!$B$6,IF(F26="Média",'08_Premissas_Custos'!$B$7,IF(F26="Alta",'08_Premissas_Custos'!$B$8,'08_Premissas_Custos'!$B$9))) | N26: ='08_Premissas_Custos'!$B$13*M26 | O26: ='08_Premissas_Custos'!$B$14*M26*(1+IF(L26="Sim",0.25,0)) | P26: ='08_Premissas_Custos'!$B$15*M26*(1+IF(I26="Sim",0.20,0)+IF(K26="Sim",0.15,0)) | Q26: ='08_Premissas_Custos'!$B$16*M26*IF(J26="Sim",1.6,0.55) | R26: ='08_Premissas_Custos'!$B$17*M26*IF(I26="Sim",1.8,0.15) | S26: ='08_Premissas_Custos'!$B$18*M26*(1+IF(I26="Sim",0.15)+IF(L26="Sim",0.10)) | T26: ='08_Premissas_Custos'!$B$19*M26*(1+IF(J26="Sim",0.15)) | U26: ='08_Premissas_Custos'!$B$20*M26*IF(K26="Sim",1.8,0.7) | V26: =SUM(N26:U26) | W26: =V26*(1-H26)*IF(E26="Fase 2",'08_Premissas_Custos'!$F$10,1) | X26: =(N26*'08_Premissas_Custos'!$C$13+O26*'08_Premissas_Custos'!$C$14+P26*'08_Premissas_Custos'!$C$15+Q26*'08_Premissas_Custos'!$C$16+R26*'08_Premissas_Custos'!$C$17+S26*'08_Premissas_Custos'!$C$18+T26*'08_Premissas_Custos'!$C$19+U26*'08_Premissas_Custos'!$C$20)*(1-H26)*IF(E26="Fase 2",'08_Premissas_Custos'!$F$10,1) | Y26: =X26*'08_Premissas_Custos'!$F$7 | Z26: =(X26+Y26)*'08_Premissas_Custos'!$F$6 | AA26: =SUM(X26:Z26) | AB26: Financeiro
A27: 22 | B27: ED | C27: Estratégia & Dados | D27: Relatórios executivos | E27: MVP | F27: Média | H27: 0 | I27: Não | J27: Sim | K27: Não | L27: Não | M27: =IF(F27="Baixa",'08_Premissas_Custos'!$B$6,IF(F27="Média",'08_Premissas_Custos'!$B$7,IF(F27="Alta",'08_Premissas_Custos'!$B$8,'08_Premissas_Custos'!$B$9))) | N27: ='08_Premissas_Custos'!$B$13*M27 | O27: ='08_Premissas_Custos'!$B$14*M27*(1+IF(L27="Sim",0.25,0)) | P27: ='08_Premissas_Custos'!$B$15*M27*(1+IF(I27="Sim",0.20,0)+IF(K27="Sim",0.15,0)) | Q27: ='08_Premissas_Custos'!$B$16*M27*IF(J27="Sim",1.6,0.55) | R27: ='08_Premissas_Custos'!$B$17*M27*IF(I27="Sim",1.8,0.15) | S27: ='08_Premissas_Custos'!$B$18*M27*(1+IF(I27="Sim",0.15)+IF(L27="Sim",0.10)) | T27: ='08_Premissas_Custos'!$B$19*M27*(1+IF(J27="Sim",0.15)) | U27: ='08_Premissas_Custos'!$B$20*M27*IF(K27="Sim",1.8,0.7) | V27: =SUM(N27:U27) | W27: =V27*(1-H27)*IF(E27="Fase 2",'08_Premissas_Custos'!$F$10,1) | X27: =(N27*'08_Premissas_Custos'!$C$13+O27*'08_Premissas_Custos'!$C$14+P27*'08_Premissas_Custos'!$C$15+Q27*'08_Premissas_Custos'!$C$16+R27*'08_Premissas_Custos'!$C$17+S27*'08_Premissas_Custos'!$C$18+T27*'08_Premissas_Custos'!$C$19+U27*'08_Premissas_Custos'!$C$20)*(1-H27)*IF(E27="Fase 2",'08_Premissas_Custos'!$F$10,1) | Y27: =X27*'08_Premissas_Custos'!$F$7 | Z27: =(X27+Y27)*'08_Premissas_Custos'!$F$6 | AA27: =SUM(X27:Z27) | AB27: Exportação
A28: 23 | B28: ED | C28: Estratégia & Dados | D28: Alertas estratégicos | E28: MVP | F28: Alta | H28: 0 | I28: Não | J28: Sim | K28: Não | L28: Não | M28: =IF(F28="Baixa",'08_Premissas_Custos'!$B$6,IF(F28="Média",'08_Premissas_Custos'!$B$7,IF(F28="Alta",'08_Premissas_Custos'!$B$8,'08_Premissas_Custos'!$B$9))) | N28: ='08_Premissas_Custos'!$B$13*M28 | O28: ='08_Premissas_Custos'!$B$14*M28*(1+IF(L28="Sim",0.25,0)) | P28: ='08_Premissas_Custos'!$B$15*M28*(1+IF(I28="Sim",0.20,0)+IF(K28="Sim",0.15,0)) | Q28: ='08_Premissas_Custos'!$B$16*M28*IF(J28="Sim",1.6,0.55) | R28: ='08_Premissas_Custos'!$B$17*M28*IF(I28="Sim",1.8,0.15) | S28: ='08_Premissas_Custos'!$B$18*M28*(1+IF(I28="Sim",0.15)+IF(L28="Sim",0.10)) | T28: ='08_Premissas_Custos'!$B$19*M28*(1+IF(J28="Sim",0.15)) | U28: ='08_Premissas_Custos'!$B$20*M28*IF(K28="Sim",1.8,0.7) | V28: =SUM(N28:U28) | W28: =V28*(1-H28)*IF(E28="Fase 2",'08_Premissas_Custos'!$F$10,1) | X28: =(N28*'08_Premissas_Custos'!$C$13+O28*'08_Premissas_Custos'!$C$14+P28*'08_Premissas_Custos'!$C$15+Q28*'08_Premissas_Custos'!$C$16+R28*'08_Premissas_Custos'!$C$17+S28*'08_Premissas_Custos'!$C$18+T28*'08_Premissas_Custos'!$C$19+U28*'08_Premissas_Custos'!$C$20)*(1-H28)*IF(E28="Fase 2",'08_Premissas_Custos'!$F$10,1) | Y28: =X28*'08_Premissas_Custos'!$F$7 | Z28: =(X28+Y28)*'08_Premissas_Custos'!$F$6 | AA28: =SUM(X28:Z28) | AB28: Sinais
A29: 24 | B29: COL | C29: Colaboradores / Meu Time | D29: Meu time | E29: MVP | F29: Alta | H29: 0 | I29: Não | J29: Não | K29: Não | L29: Não | M29: =IF(F29="Baixa",'08_Premissas_Custos'!$B$6,IF(F29="Média",'08_Premissas_Custos'!$B$7,IF(F29="Alta",'08_Premissas_Custos'!$B$8,'08_Premissas_Custos'!$B$9))) | N29: ='08_Premissas_Custos'!$B$13*M29 | O29: ='08_Premissas_Custos'!$B$14*M29*(1+IF(L29="Sim",0.25,0)) | P29: ='08_Premissas_Custos'!$B$15*M29*(1+IF(I29="Sim",0.20,0)+IF(K29="Sim",0.15,0)) | Q29: ='08_Premissas_Custos'!$B$16*M29*IF(J29="Sim",1.6,0.55) | R29: ='08_Premissas_Custos'!$B$17*M29*IF(I29="Sim",1.8,0.15) | S29: ='08_Premissas_Custos'!$B$18*M29*(1+IF(I29="Sim",0.15)+IF(L29="Sim",0.10)) | T29: ='08_Premissas_Custos'!$B$19*M29*(1+IF(J29="Sim",0.15)) | U29: ='08_Premissas_Custos'!$B$20*M29*IF(K29="Sim",1.8,0.7) | V29: =SUM(N29:U29) | W29: =V29*(1-H29)*IF(E29="Fase 2",'08_Premissas_Custos'!$F$10,1) | X29: =(N29*'08_Premissas_Custos'!$C$13+O29*'08_Premissas_Custos'!$C$14+P29*'08_Premissas_Custos'!$C$15+Q29*'08_Premissas_Custos'!$C$16+R29*'08_Premissas_Custos'!$C$17+S29*'08_Premissas_Custos'!$C$18+T29*'08_Premissas_Custos'!$C$19+U29*'08_Premissas_Custos'!$C$20)*(1-H29)*IF(E29="Fase 2",'08_Premissas_Custos'!$F$10,1) | Y29: =X29*'08_Premissas_Custos'!$F$7 | Z29: =(X29+Y29)*'08_Premissas_Custos'!$F$6 | AA29: =SUM(X29:Z29) | AB29: Mapa
A30: 25 | B30: COL | C30: Colaboradores / Meu Time | D30: Perfil do colaborador | E30: MVP | F30: Média | G30: Perfil do colaborador | H30: 0.45 | I30: Não | J30: Não | K30: Não | L30: Não | M30: =IF(F30="Baixa",'08_Premissas_Custos'!$B$6,IF(F30="Média",'08_Premissas_Custos'!$B$7,IF(F30="Alta",'08_Premissas_Custos'!$B$8,'08_Premissas_Custos'!$B$9))) | N30: ='08_Premissas_Custos'!$B$13*M30 | O30: ='08_Premissas_Custos'!$B$14*M30*(1+IF(L30="Sim",0.25,0)) | P30: ='08_Premissas_Custos'!$B$15*M30*(1+IF(I30="Sim",0.20,0)+IF(K30="Sim",0.15,0)) | Q30: ='08_Premissas_Custos'!$B$16*M30*IF(J30="Sim",1.6,0.55) | R30: ='08_Premissas_Custos'!$B$17*M30*IF(I30="Sim",1.8,0.15) | S30: ='08_Premissas_Custos'!$B$18*M30*(1+IF(I30="Sim",0.15)+IF(L30="Sim",0.10)) | T30: ='08_Premissas_Custos'!$B$19*M30*(1+IF(J30="Sim",0.15)) | U30: ='08_Premissas_Custos'!$B$20*M30*IF(K30="Sim",1.8,0.7) | V30: =SUM(N30:U30) | W30: =V30*(1-H30)*IF(E30="Fase 2",'08_Premissas_Custos'!$F$10,1) | X30: =(N30*'08_Premissas_Custos'!$C$13+O30*'08_Premissas_Custos'!$C$14+P30*'08_Premissas_Custos'!$C$15+Q30*'08_Premissas_Custos'!$C$16+R30*'08_Premissas_Custos'!$C$17+S30*'08_Premissas_Custos'!$C$18+T30*'08_Premissas_Custos'!$C$19+U30*'08_Premissas_Custos'!$C$20)*(1-H30)*IF(E30="Fase 2",'08_Premissas_Custos'!$F$10,1) | Y30: =X30*'08_Premissas_Custos'!$F$7 | Z30: =(X30+Y30)*'08_Premissas_Custos'!$F$6 | AA30: =SUM(X30:Z30) | AB30: 360
